<mujoco model="Unitree H1">
  <compiler angle="radian" meshdir="assets/"/>
  <option timestep="0.003"/>
  <size nkey="1"/>
  <visual>
    <global azimuth="-140" elevation="-30"/>
    <headlight ambient="0.3 0.3 0.3" diffuse="0.6 0.6 0.6" specular="0 0 0"/>
    <rgba haze="0.15 0.25 0.35 1"/>
  </visual>
  <statistic extent="0.8" center="1 0.7 1.5"/>
  <default class="main">
    <default class="h2">
      <joint armature="0.1" damping="1"/>
      <geom type="mesh"/>
      <site size="0.001 0.005 0.005" group="4" rgba="0.5 0.5 0.5 0.3"/>
      <default class="visual">
        <geom contype="0" conaffinity="0" group="2" material="black"/>
      </default>
      <default class="collision">
        <geom group="3"/>
      </default>
    </default>
  </default>
  <asset>
    <texture type="skybox" builtin="flat" rgb1="0 0 0" rgb2="0 0 0" width="512" height="3072"/>
    <texture type="2d" name="groundplane" builtin="checker" mark="edge" rgb1="0.2 0.3 0.4" rgb2="0.1 0.2 0.3" markrgb="0.8 0.8 0.8" width="300" height="300"/>
    <material name="black" rgba="0.1 0.1 0.1 1"/>
    <material name="white"/>
    <material name="groundplane" texture="groundplane" texuniform="true" texrepeat="5 5" reflectance="0.2"/>
    <mesh name="pelvis" file="pelvis.STL"/>
    <mesh name="left_hip_yaw_link" file="left_hip_yaw_link.STL"/>
    <mesh name="left_hip_roll_link" file="left_hip_roll_link.STL"/>
    <mesh name="left_hip_pitch_link" file="left_hip_pitch_link.STL"/>
    <mesh name="left_knee_link" file="left_knee_link.STL"/>
    <mesh name="left_ankle_link" file="left_ankle_link.STL"/>
    <mesh name="right_hip_yaw_link" file="right_hip_yaw_link.STL"/>
    <mesh name="right_hip_roll_link" file="right_hip_roll_link.STL"/>
    <mesh name="right_hip_pitch_link" file="right_hip_pitch_link.STL"/>
    <mesh name="right_knee_link" file="right_knee_link.STL"/>
    <mesh name="right_ankle_link" file="right_ankle_link.STL"/>
    <mesh name="torso_link" file="torso_link.STL"/>
    <mesh name="left_shoulder_pitch_link" file="left_shoulder_pitch_link.STL"/>
    <mesh name="left_shoulder_roll_link" file="left_shoulder_roll_link.STL"/>
    <mesh name="left_shoulder_yaw_link" file="left_shoulder_yaw_link.STL"/>
    <mesh name="left_elbow_link_ball_hand" file="left_elbow_link_ball_hand.STL"/>
    <mesh name="right_shoulder_pitch_link" file="right_shoulder_pitch_link.STL"/>
    <mesh name="right_shoulder_roll_link" file="right_shoulder_roll_link.STL"/>
    <mesh name="right_shoulder_yaw_link" file="right_shoulder_yaw_link.STL"/>
    <mesh name="right_elbow_link_ball_hand" file="right_elbow_link_ball_hand.STL"/>
    <mesh name="logo_link" file="logo_link.STL"/>
  </asset>
  <worldbody>
    <geom name="floor" size="0 0 0.05" type="plane" material="groundplane"/>
    <light pos="0 0 1.5" dir="0 0 -1" directional="true"/>
    <body name="pelvis" childclass="h2" pos="0 0 1.1">
      <inertial pos="-0.0002 4e-05 -0.04522" quat="0.498303 0.499454 -0.500496 0.501741" mass="5.39" diaginertia="0.0490211 0.0445821 0.00824619"/>
      <joint type="free" limited="false" actuatorfrclimited="false" armature="0" damping="0"/>
      <geom class="visual" mesh="pelvis"/>
      <geom class="collision" mesh="pelvis"/>
      <body name="left_hip_yaw_link" pos="0 0.0875 -0.1742">
        <inertial pos="-0.04923 0.0001 0.0072" quat="0.69699 0.219193 0.233287 0.641667" mass="2.244" diaginertia="0.00304494 0.00296885 0.00189201"/>
        <joint name="left_hip_yaw_joint" pos="0 0 0" axis="0 0 1" range="-0.43 0.43"/>
        <geom class="visual" mesh="left_hip_yaw_link"/>
        <geom class="collision" size="0.06 0.035" pos="-0.067 0 0" quat="0.707123 0 0.70709 0" type="cylinder"/>
        <body name="left_hip_roll_link" pos="0.039468 0 0">
          <inertial pos="-0.0058 -0.00319 -9e-05" quat="0.0438242 0.70721 -0.0729075 0.701867" mass="2.232" diaginertia="0.00243264 0.00225325 0.00205492"/>
          <joint name="left_hip_roll_joint" pos="0 0 0" axis="1 0 0" range="-0.43 0.43"/>
          <geom class="visual" mesh="left_hip_roll_link"/>
          <geom class="collision" mesh="left_hip_roll_link"/>
          <body name="left_hip_pitch_link" pos="0 0.11536 0">
            <inertial pos="0.00746 -0.02346 -0.08193" quat="0.979828 0.0513522 -0.0169854 -0.192382" mass="4.152" diaginertia="0.0829503 0.0821457 0.00510909"/>
            <joint name="left_hip_pitch_joint" pos="0 0 0" axis="0 1 0" range="-3.14 2.53"/>
            <geom class="visual" mesh="left_hip_pitch_link"/>
            <geom class="collision" mesh="left_hip_pitch_link"/>
            <body name="left_knee_link" pos="0 0 -0.4">
              <inertial pos="-0.00136 -0.00512 -0.1384" quat="0.626132 -0.034227 -0.0416277 0.777852" mass="1.721" diaginertia="0.0125237 0.0123104 0.0019428"/>
              <joint name="left_knee_joint" pos="0 0 0" axis="0 1 0" range="-0.26 2.05"/>
              <geom class="visual" mesh="left_knee_link"/>
              <geom class="collision" mesh="left_knee_link"/>
              <body name="left_ankle_link" pos="0 0 -0.4">
                <inertial pos="0.048568 0 -0.045609" quat="0.489385 0.510394 0.510394 0.489385" mass="0.552448" diaginertia="0.00362 0.00355701 0.000149987"/>
                <joint name="left_ankle_joint" pos="0 0 0" axis="0 1 0" range="-0.87 0.52"/>
                <geom class="visual" mesh="left_ankle_link"/>
                <geom class="collision" mesh="left_ankle_link"/>
              </body>
            </body>
          </body>
        </body>
      </body>
      <body name="right_hip_yaw_link" pos="0 -0.0875 -0.1742">
        <inertial pos="-0.04923 -0.0001 0.0072" quat="0.641667 0.233287 0.219193 0.69699" mass="2.244" diaginertia="0.00304494 0.00296885 0.00189201"/>
        <joint name="right_hip_yaw_joint" pos="0 0 0" axis="0 0 1" range="-0.43 0.43"/>
        <geom class="visual" mesh="right_hip_yaw_link"/>
        <geom class="collision" size="0.06 0.035" pos="-0.067 0 0" quat="0.707123 0 0.70709 0" type="cylinder"/>
        <body name="right_hip_roll_link" pos="0.039468 0 0">
          <inertial pos="-0.0058 0.00319 -9e-05" quat="-0.0438242 0.70721 0.0729075 0.701867" mass="2.232" diaginertia="0.00243264 0.00225325 0.00205492"/>
          <joint name="right_hip_roll_joint" pos="0 0 0" axis="1 0 0" range="-0.43 0.43"/>
          <geom class="visual" mesh="right_hip_roll_link"/>
          <geom class="collision" mesh="right_hip_roll_link"/>
          <body name="right_hip_pitch_link" pos="0 -0.11536 0">
            <inertial pos="0.00746 0.02346 -0.08193" quat="0.979828 -0.0513522 -0.0169854 0.192382" mass="4.152" diaginertia="0.0829503 0.0821457 0.00510909"/>
            <joint name="right_hip_pitch_joint" pos="0 0 0" axis="0 1 0" range="-3.14 2.53"/>
            <geom class="visual" mesh="right_hip_pitch_link"/>
            <geom class="collision" mesh="right_hip_pitch_link"/>
            <body name="right_knee_link" pos="0 0 -0.4">
              <inertial pos="-0.00136 0.00512 -0.1384" quat="0.777852 -0.0416277 -0.034227 0.626132" mass="1.721" diaginertia="0.0125237 0.0123104 0.0019428"/>
              <joint name="right_knee_joint" pos="0 0 0" axis="0 1 0" range="-0.26 2.05"/>
              <geom class="visual" mesh="right_knee_link"/>
              <geom class="collision" mesh="right_knee_link"/>
              <body name="right_ankle_link" pos="0 0 -0.4">
                <inertial pos="0.048568 0 -0.045609" quat="0.489385 0.510394 0.510394 0.489385" mass="0.552448" diaginertia="0.00362 0.00355701 0.000149987"/>
                <joint name="right_ankle_joint" pos="0 0 0" axis="0 1 0" range="-0.87 0.52"/>
                <geom class="visual" mesh="right_ankle_link"/>
                <geom class="collision" mesh="right_ankle_link"/>
              </body>
            </body>
          </body>
        </body>
      </body>
      <body name="torso_link">
        <inertial pos="0.000489 0.002797 0.20484" quat="0.999989 -0.00130808 -0.00282289 -0.00349105" mass="17.789" diaginertia="0.487315 0.409628 0.127837"/>
        <joint name="torso_joint" pos="0 0 0" axis="0 0 1" range="-2.35 2.35"/>
        <geom class="visual" mesh="torso_link"/>
        <geom class="collision" mesh="torso_link"/>
        <geom class="visual" material="white" mesh="logo_link"/>
        <site name="imu" pos="-0.04452 -0.01891 0.27756" size="0.01"/>
        <body name="left_shoulder_pitch_link" pos="0.0055 0.15535 0.42999" quat="0.976296 0.216438 0 0">
          <inertial pos="0.005045 0.053657 -0.015715" quat="0.814858 0.579236 -0.0201072 -0.00936488" mass="1.033" diaginertia="0.00129936 0.000987113 0.000858198"/>
          <joint name="left_shoulder_pitch_joint" pos="0 0 0" axis="0 1 0" range="-2.87 2.87"/>
          <geom class="visual" mesh="left_shoulder_pitch_link"/>
          <geom class="collision" mesh="left_shoulder_pitch_link"/>
          <body name="left_shoulder_roll_link" pos="-0.0055 0.0565 -0.0165" quat="0.976296 -0.216438 0 0">
            <inertial pos="0.000679 0.00115 -0.094076" quat="0.732491 0.00917179 0.0766656 0.676384" mass="0.793" diaginertia="0.00170388 0.00158256 0.00100336"/>
            <joint name="left_shoulder_roll_joint" pos="0 0 0" axis="1 0 0" range="-0.34 3.11"/>
            <geom class="visual" mesh="left_shoulder_roll_link"/>
            <geom class="collision" mesh="left_shoulder_roll_link"/>
            <body name="left_shoulder_yaw_link" pos="0 0 -0.1343">
              <inertial pos="0.01365 0.002767 -0.16266" quat="0.703042 -0.0331229 -0.0473362 0.708798" mass="0.839" diaginertia="0.00408038 0.00370367 0.000622687"/>
              <joint name="left_shoulder_yaw_joint" pos="0 0 0" axis="0 0 1" range="-1.3 4.45"/>
              <geom class="visual" mesh="left_shoulder_yaw_link"/>
              <geom class="collision" mesh="left_shoulder_yaw_link"/>
              <body name="left_elbow_link_ball_hand" pos="0.0185 0 -0.198">
                <inertial pos="0.15908 -0.000144 -0.015776" quat="0.0765232 0.720327 0.0853116 0.684102" mass="0.669" diaginertia="0.00601829 0.00600579 0.000408305"/>
                <joint name="left_elbow_joint" pos="0 0 0" axis="0 1 0" range="-1.25 2.61"/>
                <geom class="visual" mesh="left_elbow_link_ball_hand"/>
                <geom class="collision" mesh="left_elbow_link_ball_hand"/>
              </body>
            </body>
          </body>
        </body>
        <body name="right_shoulder_pitch_link" pos="0.0055 -0.15535 0.42999" quat="0.976296 -0.216438 0 0">
          <inertial pos="0.005045 -0.053657 -0.015715" quat="0.579236 0.814858 0.00936488 0.0201072" mass="1.033" diaginertia="0.00129936 0.000987113 0.000858198"/>
          <joint name="right_shoulder_pitch_joint" pos="0 0 0" axis="0 1 0" range="-2.87 2.87"/>
          <geom class="visual" mesh="right_shoulder_pitch_link"/>
          <geom class="collision" mesh="right_shoulder_pitch_link"/>
          <body name="right_shoulder_roll_link" pos="-0.0055 -0.0565 -0.0165" quat="0.976296 0.216438 0 0">
            <inertial pos="0.000679 -0.00115 -0.094076" quat="0.676384 0.0766656 0.00917179 0.732491" mass="0.793" diaginertia="0.00170388 0.00158256 0.00100336"/>
            <joint name="right_shoulder_roll_joint" pos="0 0 0" axis="1 0 0" range="-3.11 0.34"/>
            <geom class="visual" mesh="right_shoulder_roll_link"/>
            <geom class="collision" mesh="right_shoulder_roll_link"/>
            <body name="right_shoulder_yaw_link" pos="0 0 -0.1343">
              <inertial pos="0.01365 -0.002767 -0.16266" quat="0.708798 -0.0473362 -0.0331229 0.703042" mass="0.839" diaginertia="0.00408038 0.00370367 0.000622687"/>
              <joint name="right_shoulder_yaw_joint" pos="0 0 0" axis="0 0 1" range="-4.45 1.3"/>
              <geom class="visual" mesh="right_shoulder_yaw_link"/>
              <geom class="collision" mesh="right_shoulder_yaw_link"/>
              <body name="right_elbow_link_ball_hand" pos="0.0185 0 -0.198">
                <inertial pos="0.15908 0.000144 -0.015776" quat="-0.0765232 0.720327 -0.0853116 0.684102" mass="0.669" diaginertia="0.00601829 0.00600579 0.000408305"/>
                <joint name="right_elbow_joint" pos="0 0 0" axis="0 1 0" range="-1.25 2.61"/>
                <geom class="visual" mesh="right_elbow_link_ball_hand"/>
                <geom class="collision" mesh="right_elbow_link_ball_hand"/>
              </body>
            </body>
          </body>
        </body>
      </body>
    </body>
    <body name="2pelvis" childclass="h2" pos="0 -1 1.1">
      <inertial pos="-0.0002 4e-05 -0.04522" quat="0.498303 0.499454 -0.500496 0.501741" mass="5.39" diaginertia="0.0490211 0.0445821 0.00824619"/>
      <joint type="free" limited="false" actuatorfrclimited="false" armature="0" damping="0"/>
      <geom class="visual" mesh="pelvis"/>
      <geom class="collision" mesh="pelvis"/>
      <body name="2left_hip_yaw_link" pos="0 0.0875 -0.1742">
        <inertial pos="-0.04923 0.0001 0.0072" quat="0.69699 0.219193 0.233287 0.641667" mass="2.244" diaginertia="0.00304494 0.00296885 0.00189201"/>
        <joint name="2left_hip_yaw_joint" pos="0 0 0" axis="0 0 1" range="-0.43 0.43"/>
        <geom class="visual" mesh="left_hip_yaw_link"/>
        <geom class="collision" size="0.06 0.035" pos="-0.067 0 0" quat="0.707123 0 0.70709 0" type="cylinder"/>
        <body name="2left_hip_roll_link" pos="0.039468 0 0">
          <inertial pos="-0.0058 -0.00319 -9e-05" quat="0.0438242 0.70721 -0.0729075 0.701867" mass="2.232" diaginertia="0.00243264 0.00225325 0.00205492"/>
          <joint name="2left_hip_roll_joint" pos="0 0 0" axis="1 0 0" range="-0.43 0.43"/>
          <geom class="visual" mesh="left_hip_roll_link"/>
          <geom class="collision" mesh="left_hip_roll_link"/>
          <body name="2left_hip_pitch_link" pos="0 0.11536 0">
            <inertial pos="0.00746 -0.02346 -0.08193" quat="0.979828 0.0513522 -0.0169854 -0.192382" mass="4.152" diaginertia="0.0829503 0.0821457 0.00510909"/>
            <joint name="2left_hip_pitch_joint" pos="0 0 0" axis="0 1 0" range="-3.14 2.53"/>
            <geom class="visual" mesh="left_hip_pitch_link"/>
            <geom class="collision" mesh="left_hip_pitch_link"/>
            <body name="2left_knee_link" pos="0 0 -0.4">
              <inertial pos="-0.00136 -0.00512 -0.1384" quat="0.626132 -0.034227 -0.0416277 0.777852" mass="1.721" diaginertia="0.0125237 0.0123104 0.0019428"/>
              <joint name="2left_knee_joint" pos="0 0 0" axis="0 1 0" range="-0.26 2.05"/>
              <geom class="visual" mesh="left_knee_link"/>
              <geom class="collision" mesh="left_knee_link"/>
              <body name="2left_ankle_link" pos="0 0 -0.4">
                <inertial pos="0.048568 0 -0.045609" quat="0.489385 0.510394 0.510394 0.489385" mass="0.552448" diaginertia="0.00362 0.00355701 0.000149987"/>
                <joint name="2left_ankle_joint" pos="0 0 0" axis="0 1 0" range="-0.87 0.52"/>
                <geom class="visual" mesh="left_ankle_link"/>
                <geom class="collision" mesh="left_ankle_link"/>
              </body>
            </body>
          </body>
        </body>
      </body>
      <body name="2right_hip_yaw_link" pos="0 -0.0875 -0.1742">
        <inertial pos="-0.04923 -0.0001 0.0072" quat="0.641667 0.233287 0.219193 0.69699" mass="2.244" diaginertia="0.00304494 0.00296885 0.00189201"/>
        <joint name="2right_hip_yaw_joint" pos="0 0 0" axis="0 0 1" range="-0.43 0.43"/>
        <geom class="visual" mesh="right_hip_yaw_link"/>
        <geom class="collision" size="0.06 0.035" pos="-0.067 0 0" quat="0.707123 0 0.70709 0" type="cylinder"/>
        <body name="2right_hip_roll_link" pos="0.039468 0 0">
          <inertial pos="-0.0058 0.00319 -9e-05" quat="-0.0438242 0.70721 0.0729075 0.701867" mass="2.232" diaginertia="0.00243264 0.00225325 0.00205492"/>
          <joint name="2right_hip_roll_joint" pos="0 0 0" axis="1 0 0" range="-0.43 0.43"/>
          <geom class="visual" mesh="right_hip_roll_link"/>
          <geom class="collision" mesh="right_hip_roll_link"/>
          <body name="2right_hip_pitch_link" pos="0 -0.11536 0">
            <inertial pos="0.00746 0.02346 -0.08193" quat="0.979828 -0.0513522 -0.0169854 0.192382" mass="4.152" diaginertia="0.0829503 0.0821457 0.00510909"/>
            <joint name="2right_hip_pitch_joint" pos="0 0 0" axis="0 1 0" range="-3.14 2.53"/>
            <geom class="visual" mesh="right_hip_pitch_link"/>
            <geom class="collision" mesh="right_hip_pitch_link"/>
            <body name="2right_knee_link" pos="0 0 -0.4">
              <inertial pos="-0.00136 0.00512 -0.1384" quat="0.777852 -0.0416277 -0.034227 0.626132" mass="1.721" diaginertia="0.0125237 0.0123104 0.0019428"/>
              <joint name="2right_knee_joint" pos="0 0 0" axis="0 1 0" range="-0.26 2.05"/>
              <geom class="visual" mesh="right_knee_link"/>
              <geom class="collision" mesh="right_knee_link"/>
              <body name="2right_ankle_link" pos="0 0 -0.4">
                <inertial pos="0.048568 0 -0.045609" quat="0.489385 0.510394 0.510394 0.489385" mass="0.552448" diaginertia="0.00362 0.00355701 0.000149987"/>
                <joint name="2right_ankle_joint" pos="0 0 0" axis="0 1 0" range="-0.87 0.52"/>
                <geom class="visual" mesh="right_ankle_link"/>
                <geom class="collision" mesh="right_ankle_link"/>
              </body>
            </body>
          </body>
        </body>
      </body>
      <body name="2torso_link">
        <inertial pos="0.000489 0.002797 0.20484" quat="0.999989 -0.00130808 -0.00282289 -0.00349105" mass="17.789" diaginertia="0.487315 0.409628 0.127837"/>
        <joint name="2torso_joint" pos="0 0 0" axis="0 0 1" range="-2.35 2.35"/>
        <geom class="visual" mesh="torso_link"/>
        <geom class="collision" mesh="torso_link"/>
        <geom class="visual" material="white" mesh="logo_link"/>
        <site name="2imu" pos="-0.04452 -0.01891 0.27756" size="0.01"/>
        <body name="2left_shoulder_pitch_link" pos="0.0055 0.15535 0.42999" quat="0.976296 0.216438 0 0">
          <inertial pos="0.005045 0.053657 -0.015715" quat="0.814858 0.579236 -0.0201072 -0.00936488" mass="1.033" diaginertia="0.00129936 0.000987113 0.000858198"/>
          <joint name="2left_shoulder_pitch_joint" pos="0 0 0" axis="0 1 0" range="-2.87 2.87"/>
          <geom class="visual" mesh="left_shoulder_pitch_link"/>
          <geom class="collision" mesh="left_shoulder_pitch_link"/>
          <body name="2left_shoulder_roll_link" pos="-0.0055 0.0565 -0.0165" quat="0.976296 -0.216438 0 0">
            <inertial pos="0.000679 0.00115 -0.094076" quat="0.732491 0.00917179 0.0766656 0.676384" mass="0.793" diaginertia="0.00170388 0.00158256 0.00100336"/>
            <joint name="2left_shoulder_roll_joint" pos="0 0 0" axis="1 0 0" range="-0.34 3.11"/>
            <geom class="visual" mesh="left_shoulder_roll_link"/>
            <geom class="collision" mesh="left_shoulder_roll_link"/>
            <body name="2left_shoulder_yaw_link" pos="0 0 -0.1343">
              <inertial pos="0.01365 0.002767 -0.16266" quat="0.703042 -0.0331229 -0.0473362 0.708798" mass="0.839" diaginertia="0.00408038 0.00370367 0.000622687"/>
              <joint name="2left_shoulder_yaw_joint" pos="0 0 0" axis="0 0 1" range="-1.3 4.45"/>
              <geom class="visual" mesh="left_shoulder_yaw_link"/>
              <geom class="collision" mesh="left_shoulder_yaw_link"/>
              <body name="2left_elbow_link_ball_hand" pos="0.0185 0 -0.198">
                <inertial pos="0.15908 -0.000144 -0.015776" quat="0.0765232 0.720327 0.0853116 0.684102" mass="0.669" diaginertia="0.00601829 0.00600579 0.000408305"/>
                <joint name="2left_elbow_joint" pos="0 0 0" axis="0 1 0" range="-1.25 2.61"/>
                <geom class="visual" mesh="left_elbow_link_ball_hand"/>
                <geom class="collision" mesh="left_elbow_link_ball_hand"/>
              </body>
            </body>
          </body>
        </body>
        <body name="2right_shoulder_pitch_link" pos="0.0055 -0.15535 0.42999" quat="0.976296 -0.216438 0 0">
          <inertial pos="0.005045 -0.053657 -0.015715" quat="0.579236 0.814858 0.00936488 0.0201072" mass="1.033" diaginertia="0.00129936 0.000987113 0.000858198"/>
          <joint name="2right_shoulder_pitch_joint" pos="0 0 0" axis="0 1 0" range="-2.87 2.87"/>
          <geom class="visual" mesh="right_shoulder_pitch_link"/>
          <geom class="collision" mesh="right_shoulder_pitch_link"/>
          <body name="2right_shoulder_roll_link" pos="-0.0055 -0.0565 -0.0165" quat="0.976296 0.216438 0 0">
            <inertial pos="0.000679 -0.00115 -0.094076" quat="0.676384 0.0766656 0.00917179 0.732491" mass="0.793" diaginertia="0.00170388 0.00158256 0.00100336"/>
            <joint name="2right_shoulder_roll_joint" pos="0 0 0" axis="1 0 0" range="-3.11 0.34"/>
            <geom class="visual" mesh="right_shoulder_roll_link"/>
            <geom class="collision" mesh="right_shoulder_roll_link"/>
            <body name="2right_shoulder_yaw_link" pos="0 0 -0.1343">
              <inertial pos="0.01365 -0.002767 -0.16266" quat="0.708798 -0.0473362 -0.0331229 0.703042" mass="0.839" diaginertia="0.00408038 0.00370367 0.000622687"/>
              <joint name="2right_shoulder_yaw_joint" pos="0 0 0" axis="0 0 1" range="-4.45 1.3"/>
              <geom class="visual" mesh="right_shoulder_yaw_link"/>
              <geom class="collision" mesh="right_shoulder_yaw_link"/>
              <body name="2right_elbow_link_ball_hand" pos="0.0185 0 -0.198">
                <inertial pos="0.15908 0.000144 -0.015776" quat="-0.0765232 0.720327 -0.0853116 0.684102" mass="0.669" diaginertia="0.00601829 0.00600579 0.000408305"/>
                <joint name="2right_elbow_joint" pos="0 0 0" axis="0 1 0" range="-1.25 2.61"/>
                <geom class="visual" mesh="right_elbow_link_ball_hand"/>
                <geom class="collision" mesh="right_elbow_link_ball_hand"/>
              </body>
            </body>
          </body>
        </body>
      </body>
    </body>
    <body name="not_use_body" pos="0 0 20">
      <inertial pos="0 0 0" mass="0.1" diaginertia="0.1 0.1 0.1"/>
      <joint name="not_use_joint" pos="0 0 0" axis="0 0 1"/>
    </body>
    <body name="2not_use_body" pos="0 -1 20">
      <inertial pos="0 0 0" mass="0.1" diaginertia="0.1 0.1 0.1"/>
      <joint name="2not_use_joint" pos="0 0 0" axis="0 0 1"/>
    </body>
  </worldbody>
  <equality>
    <connect name="equality_constraint" body1="right_elbow_link_ball_hand" body2="2left_elbow_link_ball_hand" anchor="0.0185 0 -0.198"/>
  </equality>
  <actuator>
    <general name="right_hip_roll_joint" class="h2" joint="right_hip_roll_joint" ctrlrange="-200 200"/>
    <general name="right_hip_pitch_joint" class="h2" joint="right_hip_pitch_joint" ctrlrange="-200 200"/>
    <general name="right_knee_joint" class="h2" joint="right_knee_joint" ctrlrange="-300 300"/>
    <general name="left_hip_roll_joint" class="h2" joint="left_hip_roll_joint" ctrlrange="-200 200"/>
    <general name="left_hip_pitch_joint" class="h2" joint="left_hip_pitch_joint" ctrlrange="-200 200"/>
    <general name="left_knee_joint" class="h2" joint="left_knee_joint" ctrlrange="-300 300"/>
    <general name="torso_joint" class="h2" joint="torso_joint" ctrlrange="-200 200"/>
    <general name="left_hip_yaw_joint" class="h2" joint="left_hip_yaw_joint" ctrlrange="-200 200"/>
    <general name="right_hip_yaw_joint" class="h2" joint="right_hip_yaw_joint" ctrlrange="-200 200"/>
    <general name="not_use_joint" class="h2" joint="not_use_joint"/>
    <general name="left_ankle_joint" class="h2" joint="left_ankle_joint" ctrlrange="-40 40"/>
    <general name="right_ankle_joint" class="h2" joint="right_ankle_joint" ctrlrange="-40 40"/>
    <general name="right_shoulder_pitch_joint" class="h2" joint="right_shoulder_pitch_joint" ctrlrange="-40 40"/>
    <general name="right_shoulder_roll_joint" class="h2" joint="right_shoulder_roll_joint" ctrlrange="-40 40"/>
    <general name="right_shoulder_yaw_joint" class="h2" joint="right_shoulder_yaw_joint" ctrlrange="-18 18"/>
    <general name="right_elbow_joint" class="h2" joint="right_elbow_joint" ctrlrange="-18 18"/>
    <general name="left_shoulder_pitch_joint" class="h2" joint="left_shoulder_pitch_joint" ctrlrange="-40 40"/>
    <general name="left_shoulder_roll_joint" class="h2" joint="left_shoulder_roll_joint" ctrlrange="-40 40"/>
    <general name="left_shoulder_yaw_joint" class="h2" joint="left_shoulder_yaw_joint" ctrlrange="-18 18"/>
    <general name="left_elbow_joint" class="h2" joint="left_elbow_joint" ctrlrange="-18 18"/>
    <general name="2right_hip_roll_joint" class="h2" joint="2right_hip_roll_joint" ctrlrange="-200 200"/>
    <general name="2right_hip_pitch_joint" class="h2" joint="2right_hip_pitch_joint" ctrlrange="-200 200"/>
    <general name="2right_knee_joint" class="h2" joint="2right_knee_joint" ctrlrange="-300 300"/>
    <general name="2left_hip_roll_joint" class="h2" joint="2left_hip_roll_joint" ctrlrange="-200 200"/>
    <general name="2left_hip_pitch_joint" class="h2" joint="2left_hip_pitch_joint" ctrlrange="-200 200"/>
    <general name="2left_knee_joint" class="h2" joint="2left_knee_joint" ctrlrange="-300 300"/>
    <general name="2torso_joint" class="h2" joint="2torso_joint" ctrlrange="-200 200"/>
    <general name="2left_hip_yaw_joint" class="h2" joint="2left_hip_yaw_joint" ctrlrange="-200 200"/>
    <general name="2right_hip_yaw_joint" class="h2" joint="2right_hip_yaw_joint" ctrlrange="-200 200"/>
    <general name="2not_use_joint" class="h2" joint="2not_use_joint"/>
    <general name="2left_ankle_joint" class="h2" joint="2left_ankle_joint" ctrlrange="-40 40"/>
    <general name="2right_ankle_joint" class="h2" joint="2right_ankle_joint" ctrlrange="-40 40"/>
    <general name="2right_shoulder_pitch_joint" class="h2" joint="2right_shoulder_pitch_joint" ctrlrange="-40 40"/>
    <general name="2right_shoulder_roll_joint" class="h2" joint="2right_shoulder_roll_joint" ctrlrange="-40 40"/>
    <general name="2right_shoulder_yaw_joint" class="h2" joint="2right_shoulder_yaw_joint" ctrlrange="-18 18"/>
    <general name="2right_elbow_joint" class="h2" joint="2right_elbow_joint" ctrlrange="-18 18"/>
    <general name="2left_shoulder_pitch_joint" class="h2" joint="2left_shoulder_pitch_joint" ctrlrange="-40 40"/>
    <general name="2left_shoulder_roll_joint" class="h2" joint="2left_shoulder_roll_joint" ctrlrange="-40 40"/>
    <general name="2left_shoulder_yaw_joint" class="h2" joint="2left_shoulder_yaw_joint" ctrlrange="-18 18"/>
    <general name="2left_elbow_joint" class="h2" joint="2left_elbow_joint" ctrlrange="-18 18"/>
  </actuator>
  <sensor>
    <jointpos joint="right_hip_roll_joint" name="right_hip_roll_pos"/>
    <jointpos joint="right_hip_pitch_joint" name="right_hip_pitch_pos"/>
    <jointpos joint="right_knee_joint" name="right_knee_pos"/>
    <jointpos joint="left_hip_roll_joint" name="left_hip_roll_pos"/>
    <jointpos joint="left_hip_pitch_joint" name="left_hip_pitch_pos"/>
    <jointpos joint="left_knee_joint" name="left_knee_pos"/>
    <jointpos joint="torso_joint" name="torso_pos"/>
    <jointpos joint="left_hip_yaw_joint" name="left_hip_yaw_pos"/>
    <jointpos joint="right_hip_yaw_joint" name="right_hip_yaw_pos"/>
    <jointpos joint="not_use_joint" name="not_use_pos"/>
    <jointpos joint="left_ankle_joint" name="left_ankle_pos"/>
    <jointpos joint="right_ankle_joint" name="right_ankle_pos"/>
    <jointpos joint="right_shoulder_pitch_joint" name="right_shoulder_pitch_pos"/>
    <jointpos joint="right_shoulder_roll_joint" name="right_shoulder_roll_pos"/>
    <jointpos joint="right_shoulder_yaw_joint" name="right_shoulder_yaw_pos"/>
    <jointpos joint="right_elbow_joint" name="right_elbow_pos"/>
    <jointpos joint="left_shoulder_pitch_joint" name="left_shoulder_pitch_pos"/>
    <jointpos joint="left_shoulder_roll_joint" name="left_shoulder_roll_pos"/>
    <jointpos joint="left_shoulder_yaw_joint" name="left_shoulder_yaw_pos"/>
    <jointpos joint="left_elbow_joint" name="left_elbow_pos"/>
    <jointvel joint="right_hip_roll_joint" name="right_hip_roll_vel"/>
    <jointvel joint="right_hip_pitch_joint" name="right_hip_pitch_vel"/>
    <jointvel joint="right_knee_joint" name="right_knee_vel"/>
    <jointvel joint="left_hip_roll_joint" name="left_hip_roll_vel"/>
    <jointvel joint="left_hip_pitch_joint" name="left_hip_pitch_vel"/>
    <jointvel joint="left_knee_joint" name="left_knee_vel"/>
    <jointvel joint="torso_joint" name="torso_vel"/>
    <jointvel joint="left_hip_yaw_joint" name="left_hip_yaw_vel"/>
    <jointvel joint="right_hip_yaw_joint" name="right_hip_yaw_vel"/>
    <jointvel joint="not_use_joint" name="not_use_vel"/>
    <jointvel joint="left_ankle_joint" name="left_ankle_vel"/>
    <jointvel joint="right_ankle_joint" name="right_ankle_vel"/>
    <jointvel joint="right_shoulder_pitch_joint" name="right_shoulder_pitch_vel"/>
    <jointvel joint="right_shoulder_roll_joint" name="right_shoulder_roll_vel"/>
    <jointvel joint="right_shoulder_yaw_joint" name="right_shoulder_yaw_vel"/>
    <jointvel joint="right_elbow_joint" name="right_elbow_vel"/>
    <jointvel joint="left_shoulder_pitch_joint" name="left_shoulder_pitch_vel"/>
    <jointvel joint="left_shoulder_roll_joint" name="left_shoulder_roll_vel"/>
    <jointvel joint="left_shoulder_yaw_joint" name="left_shoulder_yaw_vel"/>
    <jointvel joint="left_elbow_joint" name="left_elbow_vel"/>
    <jointactuatorfrc joint="right_hip_roll_joint" name="right_hip_roll_torque"/>
    <jointactuatorfrc joint="right_hip_pitch_joint" name="right_hip_pitch_torque"/>
    <jointactuatorfrc joint="right_knee_joint" name="right_knee_torque"/>
    <jointactuatorfrc joint="left_hip_roll_joint" name="left_hip_roll_torque"/>
    <jointactuatorfrc joint="left_hip_pitch_joint" name="left_hip_pitch_torque"/>
    <jointactuatorfrc joint="left_knee_joint" name="left_knee_torque"/>
    <jointactuatorfrc joint="torso_joint" name="torso_torque"/>
    <jointactuatorfrc joint="left_hip_yaw_joint" name="left_hip_yaw_torque"/>
    <jointactuatorfrc joint="right_hip_yaw_joint" name="right_hip_yaw_torque"/>
    <jointactuatorfrc joint="not_use_joint" name="not_use_torque"/>
    <jointactuatorfrc joint="left_ankle_joint" name="left_ankle_torque"/>
    <jointactuatorfrc joint="right_ankle_joint" name="right_ankle_torque"/>
    <jointactuatorfrc joint="right_shoulder_pitch_joint" name="right_shoulder_pitch_torque"/>
    <jointactuatorfrc joint="right_shoulder_roll_joint" name="right_shoulder_roll_torque"/>
    <jointactuatorfrc joint="right_shoulder_yaw_joint" name="right_shoulder_yaw_torque"/>
    <jointactuatorfrc joint="right_elbow_joint" name="right_elbow_torque"/>
    <jointactuatorfrc joint="left_shoulder_pitch_joint" name="left_shoulder_pitch_torque"/>
    <jointactuatorfrc joint="left_shoulder_roll_joint" name="left_shoulder_roll_torque"/>
    <jointactuatorfrc joint="left_shoulder_yaw_joint" name="left_shoulder_yaw_torque"/>
    <jointactuatorfrc joint="left_elbow_joint" name="left_elbow_torque"/>
    <jointpos joint="2right_hip_roll_joint" name="2right_hip_roll_pos"/>
    <jointpos joint="2right_hip_pitch_joint" name="2right_hip_pitch_pos"/>
    <jointpos joint="2right_knee_joint" name="2right_knee_pos"/>
    <jointpos joint="2left_hip_roll_joint" name="2left_hip_roll_pos"/>
    <jointpos joint="2left_hip_pitch_joint" name="2left_hip_pitch_pos"/>
    <jointpos joint="2left_knee_joint" name="2left_knee_pos"/>
    <jointpos joint="2torso_joint" name="2torso_pos"/>
    <jointpos joint="2left_hip_yaw_joint" name="2left_hip_yaw_pos"/>
    <jointpos joint="2right_hip_yaw_joint" name="2right_hip_yaw_pos"/>
    <jointpos joint="2not_use_joint" name="2not_use_pos"/>
    <jointpos joint="2left_ankle_joint" name="2left_ankle_pos"/>
    <jointpos joint="2right_ankle_joint" name="2right_ankle_pos"/>
    <jointpos joint="2right_shoulder_pitch_joint" name="2right_shoulder_pitch_pos"/>
    <jointpos joint="2right_shoulder_roll_joint" name="2right_shoulder_roll_pos"/>
    <jointpos joint="2right_shoulder_yaw_joint" name="2right_shoulder_yaw_pos"/>
    <jointpos joint="2right_elbow_joint" name="2right_elbow_pos"/>
    <jointpos joint="2left_shoulder_pitch_joint" name="2left_shoulder_pitch_pos"/>
    <jointpos joint="2left_shoulder_roll_joint" name="2left_shoulder_roll_pos"/>
    <jointpos joint="2left_shoulder_yaw_joint" name="2left_shoulder_yaw_pos"/>
    <jointpos joint="2left_elbow_joint" name="2left_elbow_pos"/>
    <jointvel joint="2right_hip_roll_joint" name="2right_hip_roll_vel"/>
    <jointvel joint="2right_hip_pitch_joint" name="2right_hip_pitch_vel"/>
    <jointvel joint="2right_knee_joint" name="2right_knee_vel"/>
    <jointvel joint="2left_hip_roll_joint" name="2left_hip_roll_vel"/>
    <jointvel joint="2left_hip_pitch_joint" name="2left_hip_pitch_vel"/>
    <jointvel joint="2left_knee_joint" name="2left_knee_vel"/>
    <jointvel joint="2torso_joint" name="2torso_vel"/>
    <jointvel joint="2left_hip_yaw_joint" name="2left_hip_yaw_vel"/>
    <jointvel joint="2right_hip_yaw_joint" name="2right_hip_yaw_vel"/>
    <jointvel joint="2not_use_joint" name="2not_use_vel"/>
    <jointvel joint="2left_ankle_joint" name="2left_ankle_vel"/>
    <jointvel joint="2right_ankle_joint" name="2right_ankle_vel"/>
    <jointvel joint="2right_shoulder_pitch_joint" name="2right_shoulder_pitch_vel"/>
    <jointvel joint="2right_shoulder_roll_joint" name="2right_shoulder_roll_vel"/>
    <jointvel joint="2right_shoulder_yaw_joint" name="2right_shoulder_yaw_vel"/>
    <jointvel joint="2right_elbow_joint" name="2right_elbow_vel"/>
    <jointvel joint="2left_shoulder_pitch_joint" name="2left_shoulder_pitch_vel"/>
    <jointvel joint="2left_shoulder_roll_joint" name="2left_shoulder_roll_vel"/>
    <jointvel joint="2left_shoulder_yaw_joint" name="2left_shoulder_yaw_vel"/>
    <jointvel joint="2left_elbow_joint" name="2left_elbow_vel"/>
    <jointactuatorfrc joint="2right_hip_roll_joint" name="2right_hip_roll_torque"/>
    <jointactuatorfrc joint="2right_hip_pitch_joint" name="2right_hip_pitch_torque"/>
    <jointactuatorfrc joint="2right_knee_joint" name="2right_knee_torque"/>
    <jointactuatorfrc joint="2left_hip_roll_joint" name="2left_hip_roll_torque"/>
    <jointactuatorfrc joint="2left_hip_pitch_joint" name="2left_hip_pitch_torque"/>
    <jointactuatorfrc joint="2left_knee_joint" name="2left_knee_torque"/>
    <jointactuatorfrc joint="2torso_joint" name="2torso_torque"/>
    <jointactuatorfrc joint="2left_hip_yaw_joint" name="2left_hip_yaw_torque"/>
    <jointactuatorfrc joint="2right_hip_yaw_joint" name="2right_hip_yaw_torque"/>
    <jointactuatorfrc joint="2not_use_joint" name="2not_use_torque"/>
    <jointactuatorfrc joint="2left_ankle_joint" name="2left_ankle_torque"/>
    <jointactuatorfrc joint="2right_ankle_joint" name="2right_ankle_torque"/>
    <jointactuatorfrc joint="2right_shoulder_pitch_joint" name="2right_shoulder_pitch_torque"/>
    <jointactuatorfrc joint="2right_shoulder_roll_joint" name="2right_shoulder_roll_torque"/>
    <jointactuatorfrc joint="2right_shoulder_yaw_joint" name="2right_shoulder_yaw_torque"/>
    <jointactuatorfrc joint="2right_elbow_joint" name="2right_elbow_torque"/>
    <jointactuatorfrc joint="2left_shoulder_pitch_joint" name="2left_shoulder_pitch_torque"/>
    <jointactuatorfrc joint="2left_shoulder_roll_joint" name="2left_shoulder_roll_torque"/>
    <jointactuatorfrc joint="2left_shoulder_yaw_joint" name="2left_shoulder_yaw_torque"/>
    <jointactuatorfrc joint="2left_elbow_joint" name="2left_elbow_torque"/>
    <framequat objtype="site" objname="imu" name="imu_quat"/>
    <gyro site="imu" name="imu_gyro"/>
    <accelerometer site="imu" name="imu_acc"/>
    <framepos objtype="site" objname="imu" name="frame_pos"/>
    <framelinvel objtype="site" objname="imu" name="frame_vel"/>
    <framequat objtype="site" objname="2imu" name="2imu_quat"/>
    <gyro site="imu" name="2imu_gyro"/>
    <accelerometer site="imu" name="2imu_acc"/>
    <framepos objtype="site" objname="2imu" name="2frame_pos"/>
    <framelinvel objtype="site" objname="2imu" name="2frame_vel"/>
  </sensor>
  <keyframe>
    <key name="home" qpos="0 0 0.98 1 0 0 0 0 0 -0.4 0.8 -0.4 0 0 -0.4 0.8 -0.4 0 0 0 0 0 0 0 0 0 0 0 0 0.699929 0.714213 0 0 0 0 0 -0.4 0.8 -0.4 0 0 -0.4 0.8 -0.4 0 0 0 0 0 0 0 0 0 0"/>
  </keyframe>
</mujoco>
